<?xml version="1.0"?>
<sdf version="1.7">
  <model name="peg">
    <pose>0 0 0.025 0 0 0</pose>
    <link name="peg_y_link">
    </link>
    <link name="peg_base_link">
      <inertial>
        <mass>0.01</mass>
        <inertia>
          <ixx>0.0003542</ixx> <ixy>0.0</ixy> <ixz>0.0</ixz>
          <iyy>0.0003542</iyy> <iyz>0.0</iyz>
          <izz>0.0003542</izz>
        </inertia>
      </inertial>
      <collision name="collision">
        <geometry>
          <box>
            <size>0.049 0.15 0.05</size>
          </box>
        </geometry>
        <surface>
          <friction>
            <ode>
              <mu>0.1</mu>
              <mu2>0.1</mu2>
            </ode>
          </friction>
        </surface>
      </collision>
      <visual name="visual">
        <geometry>
          <box>
            <size>0.049 0.15 0.05</size>
          </box>
        </geometry>
        <material>
          <diffuse>1.0 1.0 1.0 1.0</diffuse>
        </material>
      </visual>
    </link>
    <link name="ft_end">
      <pose>0 -0.078 0 0 0 0</pose>
      <inertial>
        <mass>0.001</mass>
        <inertia>
          <ixx>1</ixx> <ixy>0.0</ixy> <ixz>0.0</ixz>
          <iyy>1</iyy> <iyz>0.0</iyz>
          <izz>1</izz>
        </inertia>
      </inertial>
      <visual name="visual">
        <geometry>
          <box>
            <size>0.049 0.0075 0.05</size>
          </box>
        </geometry>
        <material>
          <diffuse>0. 0. 1.0 1.0</diffuse>
        </material>
      </visual>
      <collision name="collision">
        <geometry>
          <box>
            <size>0.049 0.0075 0.05</size>
          </box>
        </geometry>
        <surface>
          <friction>
            <ode>
              <mu>0.1</mu>
              <mu2>0.1</mu2>
            </ode>
          </friction>
        </surface>
      </collision>
    </link>
    <joint name="ft_joint" type="fixed">
      <parent>peg_base_link</parent>
      <child>ft_end</child>
    </joint>
    <joint name='Pose_x' type='prismatic'>
      <parent>world</parent>
      <child>peg_y_link</child>
      <axis>
        <xyz>1.0 0.0 0.0</xyz>
        <limit>
          <effort>10</effort>
          <lower>-0.25</lower>
          <upper>0.25</upper>
        </limit>
      </axis>
    </joint>
    <joint name='Pose_y' type='prismatic'>
      <parent>peg_y_link</parent>
      <child>peg_base_link</child>
      <axis>
        <xyz>0.0 1.0 0.0</xyz>
        <limit>
          <effort>10</effort>
          <lower>-0.25</lower>
          <upper>0.0</upper>
        </limit>
      </axis>
    </joint>

  </model>
</sdf>
